Workbook

Sheet Raw_Monthly_Revenue
A1: Month | B1: Revenue
A2: Sep 2016 | B2: 252.24
A3: Oct 2016 | B3: 59090.48
A4: Dec 2016 | B4: 19.62
A5: Jan 2017 | B5: 138488.04
A6: Feb 2017 | B6: 291908.01
A7: Mar 2017 | B7: 449863.6
A8: Apr 2017 | B8: 417788.03
A9: May 2017 | B9: 592918.82
A10: Jun 2017 | B10: 511276.38
A11: Jul 2017 | B11: 592382.92
A12: Aug 2017 | B12: 674396.32
A13: Sep 2017 | B13: 727762.45
... A26: Oct 2018 | B26: 589.67

Sheet Raw_Category_Sales
A1: Product Category | B1: Revenue
A2: beleza_saude | B2: 1258681.3
A3: relogios_presentes | B3: 1205005.7
A4: cama_mesa_banho | B4: 1036988.7
A5: esporte_lazer | B5: 988048.97
A6: informatica_acessorios | B6: 911954.32
A7: moveis_decoracao | B7: 729762.49
A8: cool_stuff | B8: 635290.85
A9: utilidades_domesticas | B9: 632248.66
A10: automotivo | B10: 592720.11
A11: ferramentas_jardim | B11: 485256.46
A12: brinquedos | B12: 483946.6
A13: bebes | B13: 411764.89
... A16: moveis_escritorio | B16: 273960.7

Sheet Raw_State_Revenue
A1: State | B1: Revenue
A2: SP | B2: 5998227
A3: RJ | B3: 2144379.7
A4: MG | B4: 1872257.3
A5: RS | B5: 890898.54
A6: PR | B6: 811156.38
A7: SC | B7: 623086.43
A8: BA | B8: 616645.82
A9: DF | B9: 355141.08
A10: GO | B10: 350092.31
A11: ES | B11: 325967.55
A12: PE | B12: 324850.44
A13: CE | B13: 279464.03
... A28: RR | B28: 10064.62

Sheet Dashboard
B2: 🛒 E-COMMERCE PERFORMANCE DASHBOARD
B5: 💰 | D5: 📦 | F5: 📈 | H5: 🏆
B6: TOTAL REVENUE | D6: TOTAL MONTHS | F6: PEAK REVENUE | H6: TOP CATEGORY
B7: =SUM(Raw_Monthly_Revenue!B2:B26) -> 16008872 | D7: =COUNTA(Raw_Monthly_Revenue!A2:A26) -> 25 | F7: =MAX(Raw_Monthly_Revenue!B2:B26) -> 1194882.8 | H7: =Raw_Category_Sales!A2 -> beleza_saude
B8: FY 2016–2018 | D8: FY 2016–2018 | F8: FY 2016–2018 | H8: FY 2016–2018
B10: 📅 MONTHLY REVENUE TREND | F10: 🏆 TOP 15 CATEGORIES BY REVENUE
B11: Month | C11: Revenue | D11: MoM Change | E11: Cumulative | F11: Category | G11: Revenue | H11: Share % | I11: Rank
B12: =Raw_Monthly_Revenue!A2 -> Sep 2016 | C12: =Raw_Monthly_Revenue!B2 -> 252.24 | D12: "—" | E12: =SUM(Raw_Monthly_Revenue!B$2:B2) -> 252.24 | F12: =Raw_Category_Sales!A2 -> beleza_saude | G12: =Raw_Category_Sales!B2 -> 1258681.3 | H12: =Raw_Category_Sales!B2/SUM(Raw_Category_Sales!B$2:B$16) -> 0.12139565 | I12: 1
B13: =Raw_Monthly_Revenue!A3 -> Oct 2016 | C13: =Raw_Monthly_Revenue!B3 -> 59090.48 | D13: =IF(C12=0,"—",(C13-C12)/C12) -> 233.26292 | E13: =SUM(Raw_Monthly_Revenue!B$2:B3) -> 59342.72 | F13: =Raw_Category_Sales!A3 -> relogios_presentes | G13: =Raw_Category_Sales!B3 -> 1205005.7 | H13: =Raw_Category_Sales!B3/SUM(Raw_Category_Sales!B$2:B$16) -> 0.11621881 | I13: 2
B14: =Raw_Monthly_Revenue!A4 -> Dec 2016 | C14: =Raw_Monthly_Revenue!B4 -> 19.62 | D14: =IF(C13=0,"—",(C14-C13)/C13) -> -0.99966797 | E14: =SUM(Raw_Monthly_Revenue!B$2:B4) -> 59362.34 | F14: =Raw_Category_Sales!A4 -> cama_mesa_banho | G14: =Raw_Category_Sales!B4 -> 1036988.7 | H14: =Raw_Category_Sales!B4/SUM(Raw_Category_Sales!B$2:B$16) -> 0.10001413 | I14: 3
B15: =Raw_Monthly_Revenue!A5 -> Jan 2017 | C15: =Raw_Monthly_Revenue!B5 -> 138488.04 | D15: =IF(C14=0,"—",(C15-C14)/C14) -> 7057.5138 | E15: =SUM(Raw_Monthly_Revenue!B$2:B5) -> 197850.38 | F15: =Raw_Category_Sales!A5 -> esporte_lazer | G15: =Raw_Category_Sales!B5 -> 988048.97 | H15: =Raw_Category_Sales!B5/SUM(Raw_Category_Sales!B$2:B$16) -> 0.095294053 | I15: 4
B16: =Raw_Monthly_Revenue!A6 -> Feb 2017 | C16: =Raw_Monthly_Revenue!B6 -> 291908.01 | D16: =IF(C15=0,"—",(C16-C15)/C15) -> 1.1078211 | E16: =SUM(Raw_Monthly_Revenue!B$2:B6) -> 489758.39 | F16: =Raw_Category_Sales!A6 -> informatica_acessorios | G16: =Raw_Category_Sales!B6 -> 911954.32 | H16: =Raw_Category_Sales!B6/SUM(Raw_Category_Sales!B$2:B$16) -> 0.087954976 | I16: 5
B17: =Raw_Monthly_Revenue!A7 -> Mar 2017 | C17: =Raw_Monthly_Revenue!B7 -> 449863.6 | D17: =IF(C16=0,"—",(C17-C16)/C16) -> 0.54111427 | E17: =SUM(Raw_Monthly_Revenue!B$2:B7) -> 939621.99 | F17: =Raw_Category_Sales!A7 -> moveis_decoracao | G17: =Raw_Category_Sales!B7 -> 729762.49 | H17: =Raw_Category_Sales!B7/SUM(Raw_Category_Sales!B$2:B$16) -> 0.070383177 | I17: 6
B18: =Raw_Monthly_Revenue!A8 -> Apr 2017 | C18: =Raw_Monthly_Revenue!B8 -> 417788.03 | D18: =IF(C17=0,"—",(C18-C17)/C17) -> -0.071300656 | E18: =SUM(Raw_Monthly_Revenue!B$2:B8) -> 1357410 | F18: =Raw_Category_Sales!A8 -> cool_stuff | G18: =Raw_Category_Sales!B8 -> 635290.85 | H18: =Raw_Category_Sales!B8/SUM(Raw_Category_Sales!B$2:B$16) -> 0.0612717 | I18: 7
B19: =Raw_Monthly_Revenue!A9 -> May 2017 | C19: =Raw_Monthly_Revenue!B9 -> 592918.82 | D19: =IF(C18=0,"—",(C19-C18)/C18) -> 0.41918575 | E19: =SUM(Raw_Monthly_Revenue!B$2:B9) -> 1950328.8 | F19: =Raw_Category_Sales!A9 -> utilidades_domesticas | G19: =Raw_Category_Sales!B9 -> 632248.66 | H19: =Raw_Category_Sales!B9/SUM(Raw_Category_Sales!B$2:B$16) -> 0.060978291 | I19: 8
B20: =Raw_Monthly_Revenue!A10 -> Jun 2017 | C20: =Raw_Monthly_Revenue!B10 -> 511276.38 | D20: =IF(C19=0,"—",(C20-C19)/C19) -> -0.13769581 | E20: =SUM(Raw_Monthly_Revenue!B$2:B10) -> 2461605.2 | F20: =Raw_Category_Sales!A10 -> automotivo | G20: =Raw_Category_Sales!B10 -> 592720.11 | H20: =Raw_Category_Sales!B10/SUM(Raw_Category_Sales!B$2:B$16) -> 0.057165893 | I20: 9
B21: =Raw_Monthly_Revenue!A11 -> Jul 2017 | C21: =Raw_Monthly_Revenue!B11 -> 592382.92 | D21: =IF(C20=0,"—",(C21-C20)/C20) -> 0.15863541 | E21: =SUM(Raw_Monthly_Revenue!B$2:B11) -> 3053988.1 | F21: =Raw_Category_Sales!A11 -> ferramentas_jardim | G21: =Raw_Category_Sales!B11 -> 485256.46 | H21: =Raw_Category_Sales!B11/SUM(Raw_Category_Sales!B$2:B$16) -> 0.04680138 | I21: 10
B22: =Raw_Monthly_Revenue!A12 -> Aug 2017 | C22: =Raw_Monthly_Revenue!B12 -> 674396.32 | D22: =IF(C21=0,"—",(C22-C21)/C21) -> 0.1384466 | E22: =SUM(Raw_Monthly_Revenue!B$2:B12) -> 3728384.5 | F22: =Raw_Category_Sales!A12 -> brinquedos | G22: =Raw_Category_Sales!B12 -> 483946.6 | H22: =Raw_Category_Sales!B12/SUM(Raw_Category_Sales!B$2:B$16) -> 0.046675048 | I22: 11
B23: =Raw_Monthly_Revenue!A13 -> Sep 2017 | C23: =Raw_Monthly_Revenue!B13 -> 727762.45 | D23: =IF(C22=0,"—",(C23-C22)/C22) -> 0.079131704 | E23: =SUM(Raw_Monthly_Revenue!B$2:B13) -> 4456146.9 | F23: =Raw_Category_Sales!A13 -> bebes | G23: =Raw_Category_Sales!B13 -> 411764.89 | H23: =Raw_Category_Sales!B13/SUM(Raw_Category_Sales!B$2:B$16) -> 0.039713361 | I23: 12
B24: =Raw_Monthly_Revenue!A14 -> Oct 2017 | C24: =Raw_Monthly_Revenue!B14 -> 779677.88 | D24: =IF(C23=0,"—",(C24-C23)/C23) -> 0.071335681 | E24: =SUM(Raw_Monthly_Revenue!B$2:B14) -> 5235824.8 | F24: =Raw_Category_Sales!A14 -> perfumaria | G24: =Raw_Category_Sales!B14 -> 399124.87 | H24: =Raw_Category_Sales!B14/SUM(Raw_Category_Sales!B$2:B$16) -> 0.038494273 | I24: 13
... B26: =Raw_Monthly_Revenue!A16 -> Dec 2017 | C26: =Raw_Monthly_Revenue!B16 -> 878401.48 | D26: =IF(C25=0,"—",(C26-C25)/C25) -> -0.2648639 | E26: =SUM(Raw_Monthly_Revenue!B$2:B16) -> 7309109.1 | F26: =Raw_Category_Sales!A16 -> moveis_escritorio | G26: =Raw_Category_Sales!B16 -> 273960.7 | H26: =Raw_Category_Sales!B16/SUM(Raw_Category_Sales!B$2:B$16) -> 0.026422603 | I26: 15
B27: =Raw_Monthly_Revenue!A17 -> Jan 2018 | C27: =Raw_Monthly_Revenue!B17 -> 1115004.2 | D27: =IF(C26=0,"—",(C27-C26)/C26) -> 0.26935599 | E27: =SUM(Raw_Monthly_Revenue!B$2:B17) -> 8424113.2
B28: =Raw_Monthly_Revenue!A18 -> Feb 2018 | C28: =Raw_Monthly_Revenue!B18 -> 992463.34 | D28: =IF(C27=0,"—",(C28-C27)/C27) -> -0.10990169 | E28: =SUM(Raw_Monthly_Revenue!B$2:B18) -> 9416576.6
B29: =Raw_Monthly_Revenue!A19 -> Mar 2018 | C29: =Raw_Monthly_Revenue!B19 -> 1159652.1 | D29: =IF(C28=0,"—",(C29-C28)/C28) -> 0.16845839 | E29: =SUM(Raw_Monthly_Revenue!B$2:B19) -> 10576229
B30: =Raw_Monthly_Revenue!A20 -> Apr 2018 | C30: =Raw_Monthly_Revenue!B20 -> 1160785.5 | D30: =IF(C29=0,"—",(C30-C29)/C29) -> 0.00097732758 | E30: =SUM(Raw_Monthly_Revenue!B$2:B20) -> 11737014
B31: =Raw_Monthly_Revenue!A21 -> May 2018 | C31: =Raw_Monthly_Revenue!B21 -> 1153982.1 | D31: =IF(C30=0,"—",(C31-C30)/C30) -> -0.005860971 | E31: =SUM(Raw_Monthly_Revenue!B$2:B21) -> 12890996
B32: =Raw_Monthly_Revenue!A22 -> Jun 2018 | C32: =Raw_Monthly_Revenue!B22 -> 1023880.5 | D32: =IF(C31=0,"—",(C32-C31)/C31) -> -0.11274148 | E32: =SUM(Raw_Monthly_Revenue!B$2:B22) -> 13914877
B33: =Raw_Monthly_Revenue!A23 -> Jul 2018 | C33: =Raw_Monthly_Revenue!B23 -> 1066540.8 | D33: =IF(C32=0,"—",(C33-C32)/C32) -> 0.041665263 | E33: =SUM(Raw_Monthly_Revenue!B$2:B23) -> 14981418
B34: =Raw_Monthly_Revenue!A24 -> Aug 2018 | C34: =Raw_Monthly_Revenue!B24 -> 1022425.3 | D34: =IF(C33=0,"—",(C34-C33)/C33) -> -0.041363098 | E34: =SUM(Raw_Monthly_Revenue!B$2:B24) -> 16003843
B35: =Raw_Monthly_Revenue!A25 -> Sep 2018 | C35: =Raw_Monthly_Revenue!B25 -> 4439.54 | D35: =IF(C34=0,"—",(C35-C34)/C34) -> -0.99565783 | E35: =SUM(Raw_Monthly_Revenue!B$2:B25) -> 16008282
B36: =Raw_Monthly_Revenue!A26 -> Oct 2018 | C36: =Raw_Monthly_Revenue!B26 -> 589.67 | D36: =IF(C35=0,"—",(C36-C35)/C35) -> -0.86717768 | E36: =SUM(Raw_Monthly_Revenue!B$2:B26) -> 16008872
B37: TOTAL | C37: =SUM(Raw_Monthly_Revenue!B2:B26) -> 16008872 | E37: =SUM(Raw_Monthly_Revenue!B2:B26) -> 16008872
B39: 🗺️ REVENUE BY STATE (TOP 10)
B40: State | C40: Revenue | D40: Share % | E40: Rank
B41: =Raw_State_Revenue!A2 -> SP | C41: =Raw_State_Revenue!B2 -> 5998227 | D41: =Raw_State_Revenue!B2/SUM(Raw_State_Revenue!B$2:B$28) -> 0.37468142 | E41: 1
B42: =Raw_State_Revenue!A3 -> RJ | C42: =Raw_State_Revenue!B3 -> 2144379.7 | D42: =Raw_State_Revenue!B3/SUM(Raw_State_Revenue!B$2:B$28) -> 0.13394945 | E42: 2
B43: =Raw_State_Revenue!A4 -> MG | C43: =Raw_State_Revenue!B4 -> 1872257.3 | D43: =Raw_State_Revenue!B4/SUM(Raw_State_Revenue!B$2:B$28) -> 0.11695123 | E43: 3
B44: =Raw_State_Revenue!A5 -> RS | C44: =Raw_State_Revenue!B5 -> 890898.54 | D44: =Raw_State_Revenue!B5/SUM(Raw_State_Revenue!B$2:B$28) -> 0.0556503 | E44: 4
B45: =Raw_State_Revenue!A6 -> PR | C45: =Raw_State_Revenue!B6 -> 811156.38 | D45: =Raw_State_Revenue!B6/SUM(Raw_State_Revenue!B$2:B$28) -> 0.050669177 | E45: 5
B46: =Raw_State_Revenue!A7 -> SC | C46: =Raw_State_Revenue!B7 -> 623086.43 | D46: =Raw_State_Revenue!B7/SUM(Raw_State_Revenue!B$2:B$28) -> 0.03892132 | E46: 6
...
